----------------------------------------------------------------------------------------------------
[INFO] - 2020-06-20 00:23:45,775

Source log file: /usr/local/lib64/python3.6/site-packages/django/utils/autoreload.py line: 598

Watching for file changes with StatReloader
----------------------------------------------------------------------------------------------------
[INFO] - 2020-06-20 00:25:40,430

Source log file: /usr/local/lib64/python3.6/site-packages/django/core/servers/basehttp.py line: 157

"GET / HTTP/1.1" 200 2000
----------------------------------------------------------------------------------------------------
[INFO] - 2020-06-20 00:25:42,639

Source log file: /usr/local/lib64/python3.6/site-packages/django/core/servers/basehttp.py line: 157

"GET /host/ HTTP/1.1" 200 79
----------------------------------------------------------------------------------------------------
[ERROR] - 2020-06-20 00:25:45,695

Source log file: /root/httptracker/httptracker/ec2/ec2.py line: 42

Traceback (most recent call last):
  File "/usr/lib64/python3.6/urllib/request.py", line 1318, in do_open
    encode_chunked=req.has_header('Transfer-encoding'))
  File "/usr/lib64/python3.6/http/client.py", line 1254, in request
    self._send_request(method, url, body, headers, encode_chunked)
  File "/usr/lib64/python3.6/http/client.py", line 1300, in _send_request
    self.endheaders(body, encode_chunked=encode_chunked)
  File "/usr/lib64/python3.6/http/client.py", line 1249, in endheaders
    self._send_output(message_body, encode_chunked=encode_chunked)
  File "/usr/lib64/python3.6/http/client.py", line 1036, in _send_output
    self.send(msg)
  File "/usr/lib64/python3.6/http/client.py", line 974, in send
    self.connect()
  File "/usr/lib64/python3.6/http/client.py", line 946, in connect
    (self.host,self.port), self.timeout, self.source_address)
  File "/usr/lib64/python3.6/socket.py", line 724, in create_connection
    raise err
  File "/usr/lib64/python3.6/socket.py", line 713, in create_connection
    sock.connect(sa)
OSError: [Errno 113] No route to host

During handling of the above exception, another exception occurred:

Traceback (most recent call last):
  File "/root/httptracker/httptracker/ec2/ec2.py", line 30, in query
    with urllib.request.urlopen(response) as data:
  File "/usr/lib64/python3.6/urllib/request.py", line 223, in urlopen
    return opener.open(url, data, timeout)
  File "/usr/lib64/python3.6/urllib/request.py", line 526, in open
    response = self._open(req, data)
  File "/usr/lib64/python3.6/urllib/request.py", line 544, in _open
    '_open', req)
  File "/usr/lib64/python3.6/urllib/request.py", line 504, in _call_chain
    result = func(*args)
  File "/usr/lib64/python3.6/urllib/request.py", line 1346, in http_open
    return self.do_open(http.client.HTTPConnection, req)
  File "/usr/lib64/python3.6/urllib/request.py", line 1320, in do_open
    raise URLError(err)
urllib.error.URLError: <urlopen error [Errno 113] No route to host>

----------------------------------------------------------------------------------------------------
[ERROR] - 2020-06-20 00:25:48,763

Source log file: /root/httptracker/httptracker/ec2/ec2.py line: 42

Traceback (most recent call last):
  File "/usr/lib64/python3.6/urllib/request.py", line 1318, in do_open
    encode_chunked=req.has_header('Transfer-encoding'))
  File "/usr/lib64/python3.6/http/client.py", line 1254, in request
    self._send_request(method, url, body, headers, encode_chunked)
  File "/usr/lib64/python3.6/http/client.py", line 1300, in _send_request
    self.endheaders(body, encode_chunked=encode_chunked)
  File "/usr/lib64/python3.6/http/client.py", line 1249, in endheaders
    self._send_output(message_body, encode_chunked=encode_chunked)
  File "/usr/lib64/python3.6/http/client.py", line 1036, in _send_output
    self.send(msg)
  File "/usr/lib64/python3.6/http/client.py", line 974, in send
    self.connect()
  File "/usr/lib64/python3.6/http/client.py", line 946, in connect
    (self.host,self.port), self.timeout, self.source_address)
  File "/usr/lib64/python3.6/socket.py", line 724, in create_connection
    raise err
  File "/usr/lib64/python3.6/socket.py", line 713, in create_connection
    sock.connect(sa)
OSError: [Errno 113] No route to host

During handling of the above exception, another exception occurred:

Traceback (most recent call last):
  File "/root/httptracker/httptracker/ec2/ec2.py", line 30, in query
    with urllib.request.urlopen(response) as data:
  File "/usr/lib64/python3.6/urllib/request.py", line 223, in urlopen
    return opener.open(url, data, timeout)
  File "/usr/lib64/python3.6/urllib/request.py", line 526, in open
    response = self._open(req, data)
  File "/usr/lib64/python3.6/urllib/request.py", line 544, in _open
    '_open', req)
  File "/usr/lib64/python3.6/urllib/request.py", line 504, in _call_chain
    result = func(*args)
  File "/usr/lib64/python3.6/urllib/request.py", line 1346, in http_open
    return self.do_open(http.client.HTTPConnection, req)
  File "/usr/lib64/python3.6/urllib/request.py", line 1320, in do_open
    raise URLError(err)
urllib.error.URLError: <urlopen error [Errno 113] No route to host>

----------------------------------------------------------------------------------------------------
[INFO] - 2020-06-20 00:25:48,764

Source log file: /usr/local/lib64/python3.6/site-packages/django/core/servers/basehttp.py line: 157

"GET /ec2/ HTTP/1.1" 200 162
