
----------------------------------------------------------------------------------------------------
[INFO] - 2020-06-20 18:06:40,603

Source log file: /usr/local/lib64/python3.6/site-packages/django/utils/autoreload.py line: 598

Watching for file changes with StatReloader
----------------------------------------------------------------------------------------------------
[INFO] - 2020-06-20 18:55:15,968

Source log file: /usr/local/lib64/python3.6/site-packages/django/utils/autoreload.py line: 222

/root/httptracker/httptracker/httptracker/urls.py changed, reloading.
----------------------------------------------------------------------------------------------------
[INFO] - 2020-06-20 18:55:16,221

Source log file: /usr/local/lib64/python3.6/site-packages/django/utils/autoreload.py line: 598

Watching for file changes with StatReloader
----------------------------------------------------------------------------------------------------
[INFO] - 2020-06-20 19:17:16,671

Source log file: /usr/local/lib64/python3.6/site-packages/django/utils/autoreload.py line: 598

Watching for file changes with StatReloader
----------------------------------------------------------------------------------------------------
[INFO] - 2020-06-20 19:18:55,621

Source log file: /usr/local/lib64/python3.6/site-packages/django/utils/autoreload.py line: 222

/root/httptracker/httptracker/traceroute/views.py changed, reloading.
----------------------------------------------------------------------------------------------------
[INFO] - 2020-06-20 19:18:55,871

Source log file: /usr/local/lib64/python3.6/site-packages/django/utils/autoreload.py line: 598

Watching for file changes with StatReloader
----------------------------------------------------------------------------------------------------
[INFO] - 2020-06-20 19:22:02,383

Source log file: /usr/local/lib64/python3.6/site-packages/django/utils/autoreload.py line: 598

Watching for file changes with StatReloader
----------------------------------------------------------------------------------------------------
[INFO] - 2020-06-20 19:22:25,328

Source log file: /usr/local/lib64/python3.6/site-packages/django/utils/autoreload.py line: 598

Watching for file changes with StatReloader
----------------------------------------------------------------------------------------------------
[INFO] - 2020-06-21 16:14:35,887

Source log file: /usr/local/lib64/python3.6/site-packages/django/utils/autoreload.py line: 598

Watching for file changes with StatReloader
----------------------------------------------------------------------------------------------------
[INFO] - 2020-06-21 16:15:44,916

Source log file: /usr/local/lib64/python3.6/site-packages/django/core/servers/basehttp.py line: 157

"GET / HTTP/1.1" 200 2022
----------------------------------------------------------------------------------------------------
[INFO] - 2020-06-21 16:15:45,187

Source log file: /usr/local/lib64/python3.6/site-packages/django/core/servers/basehttp.py line: 157

"GET /static/js/jquery-3.5.1.min.js HTTP/1.1" 200 89476
----------------------------------------------------------------------------------------------------
[WARNING] - 2020-06-21 16:15:45,557

Source log file: /usr/local/lib64/python3.6/site-packages/django/utils/log.py line: 228

Not Found: /favicon.ico
----------------------------------------------------------------------------------------------------
[WARNING] - 2020-06-21 16:15:45,557

Source log file: /usr/local/lib64/python3.6/site-packages/django/core/servers/basehttp.py line: 157

"GET /favicon.ico HTTP/1.1" 404 2307
----------------------------------------------------------------------------------------------------
[INFO] - 2020-06-21 16:15:47,522

Source log file: /usr/local/lib64/python3.6/site-packages/django/core/servers/basehttp.py line: 157

"GET /host/ HTTP/1.1" 200 79
----------------------------------------------------------------------------------------------------
[ERROR] - 2020-06-21 16:15:50,601

Source log file: /root/httptracker/httptracker/ec2/ec2.py line: 42

Traceback (most recent call last):
  File "/usr/lib64/python3.6/urllib/request.py", line 1318, in do_open
    encode_chunked=req.has_header('Transfer-encoding'))
  File "/usr/lib64/python3.6/http/client.py", line 1254, in request
    self._send_request(method, url, body, headers, encode_chunked)
  File "/usr/lib64/python3.6/http/client.py", line 1300, in _send_request
    self.endheaders(body, encode_chunked=encode_chunked)
  File "/usr/lib64/python3.6/http/client.py", line 1249, in endheaders
    self._send_output(message_body, encode_chunked=encode_chunked)
  File "/usr/lib64/python3.6/http/client.py", line 1036, in _send_output
    self.send(msg)
  File "/usr/lib64/python3.6/http/client.py", line 974, in send
    self.connect()
  File "/usr/lib64/python3.6/http/client.py", line 946, in connect
    (self.host,self.port), self.timeout, self.source_address)
  File "/usr/lib64/python3.6/socket.py", line 724, in create_connection
    raise err
  File "/usr/lib64/python3.6/socket.py", line 713, in create_connection
    sock.connect(sa)
OSError: [Errno 113] No route to host

During handling of the above exception, another exception occurred:

Traceback (most recent call last):
  File "/root/httptracker/httptracker/ec2/ec2.py", line 30, in query
    with urllib.request.urlopen(response) as data:
  File "/usr/lib64/python3.6/urllib/request.py", line 223, in urlopen
    return opener.open(url, data, timeout)
  File "/usr/lib64/python3.6/urllib/request.py", line 526, in open
    response = self._open(req, data)
  File "/usr/lib64/python3.6/urllib/request.py", line 544, in _open
    '_open', req)
  File "/usr/lib64/python3.6/urllib/request.py", line 504, in _call_chain
    result = func(*args)
  File "/usr/lib64/python3.6/urllib/request.py", line 1346, in http_open
    return self.do_open(http.client.HTTPConnection, req)
  File "/usr/lib64/python3.6/urllib/request.py", line 1320, in do_open
    raise URLError(err)
urllib.error.URLError: <urlopen error [Errno 113] No route to host>

----------------------------------------------------------------------------------------------------
[ERROR] - 2020-06-21 16:15:53,666

Source log file: /root/httptracker/httptracker/ec2/ec2.py line: 42

Traceback (most recent call last):
  File "/usr/lib64/python3.6/urllib/request.py", line 1318, in do_open
    encode_chunked=req.has_header('Transfer-encoding'))
  File "/usr/lib64/python3.6/http/client.py", line 1254, in request
    self._send_request(method, url, body, headers, encode_chunked)
  File "/usr/lib64/python3.6/http/client.py", line 1300, in _send_request
    self.endheaders(body, encode_chunked=encode_chunked)
  File "/usr/lib64/python3.6/http/client.py", line 1249, in endheaders
    self._send_output(message_body, encode_chunked=encode_chunked)
  File "/usr/lib64/python3.6/http/client.py", line 1036, in _send_output
    self.send(msg)
  File "/usr/lib64/python3.6/http/client.py", line 974, in send
    self.connect()
  File "/usr/lib64/python3.6/http/client.py", line 946, in connect
    (self.host,self.port), self.timeout, self.source_address)
  File "/usr/lib64/python3.6/socket.py", line 724, in create_connection
    raise err
  File "/usr/lib64/python3.6/socket.py", line 713, in create_connection
    sock.connect(sa)
OSError: [Errno 113] No route to host

During handling of the above exception, another exception occurred:

Traceback (most recent call last):
  File "/root/httptracker/httptracker/ec2/ec2.py", line 30, in query
    with urllib.request.urlopen(response) as data:
  File "/usr/lib64/python3.6/urllib/request.py", line 223, in urlopen
    return opener.open(url, data, timeout)
  File "/usr/lib64/python3.6/urllib/request.py", line 526, in open
    response = self._open(req, data)
  File "/usr/lib64/python3.6/urllib/request.py", line 544, in _open
    '_open', req)
  File "/usr/lib64/python3.6/urllib/request.py", line 504, in _call_chain
    result = func(*args)
  File "/usr/lib64/python3.6/urllib/request.py", line 1346, in http_open
    return self.do_open(http.client.HTTPConnection, req)
  File "/usr/lib64/python3.6/urllib/request.py", line 1320, in do_open
    raise URLError(err)
urllib.error.URLError: <urlopen error [Errno 113] No route to host>

----------------------------------------------------------------------------------------------------
[INFO] - 2020-06-21 16:15:53,669

Source log file: /usr/local/lib64/python3.6/site-packages/django/core/servers/basehttp.py line: 157

"GET /ec2/ HTTP/1.1" 200 162
----------------------------------------------------------------------------------------------------
[INFO] - 2020-06-21 16:15:56,670

Source log file: /usr/local/lib64/python3.6/site-packages/django/core/servers/basehttp.py line: 157

"GET /traceroute/ HTTP/1.1" 200 343
----------------------------------------------------------------------------------------------------
[INFO] - 2020-06-21 16:15:56,782

Source log file: /usr/local/lib64/python3.6/site-packages/django/core/servers/basehttp.py line: 157

"GET /host/ HTTP/1.1" 200 79
----------------------------------------------------------------------------------------------------
[ERROR] - 2020-06-21 16:15:59,843

Source log file: /root/httptracker/httptracker/ec2/ec2.py line: 42

Traceback (most recent call last):
  File "/usr/lib64/python3.6/urllib/request.py", line 1318, in do_open
    encode_chunked=req.has_header('Transfer-encoding'))
  File "/usr/lib64/python3.6/http/client.py", line 1254, in request
    self._send_request(method, url, body, headers, encode_chunked)
  File "/usr/lib64/python3.6/http/client.py", line 1300, in _send_request
    self.endheaders(body, encode_chunked=encode_chunked)
  File "/usr/lib64/python3.6/http/client.py", line 1249, in endheaders
    self._send_output(message_body, encode_chunked=encode_chunked)
  File "/usr/lib64/python3.6/http/client.py", line 1036, in _send_output
    self.send(msg)
  File "/usr/lib64/python3.6/http/client.py", line 974, in send
    self.connect()
  File "/usr/lib64/python3.6/http/client.py", line 946, in connect
    (self.host,self.port), self.timeout, self.source_address)
  File "/usr/lib64/python3.6/socket.py", line 724, in create_connection
    raise err
  File "/usr/lib64/python3.6/socket.py", line 713, in create_connection
    sock.connect(sa)
OSError: [Errno 113] No route to host

During handling of the above exception, another exception occurred:

Traceback (most recent call last):
  File "/root/httptracker/httptracker/ec2/ec2.py", line 30, in query
    with urllib.request.urlopen(response) as data:
  File "/usr/lib64/python3.6/urllib/request.py", line 223, in urlopen
    return opener.open(url, data, timeout)
  File "/usr/lib64/python3.6/urllib/request.py", line 526, in open
    response = self._open(req, data)
  File "/usr/lib64/python3.6/urllib/request.py", line 544, in _open
    '_open', req)
  File "/usr/lib64/python3.6/urllib/request.py", line 504, in _call_chain
    result = func(*args)
  File "/usr/lib64/python3.6/urllib/request.py", line 1346, in http_open
    return self.do_open(http.client.HTTPConnection, req)
  File "/usr/lib64/python3.6/urllib/request.py", line 1320, in do_open
    raise URLError(err)
urllib.error.URLError: <urlopen error [Errno 113] No route to host>

----------------------------------------------------------------------------------------------------
[ERROR] - 2020-06-21 16:16:02,915

Source log file: /root/httptracker/httptracker/ec2/ec2.py line: 42

Traceback (most recent call last):
  File "/usr/lib64/python3.6/urllib/request.py", line 1318, in do_open
    encode_chunked=req.has_header('Transfer-encoding'))
  File "/usr/lib64/python3.6/http/client.py", line 1254, in request
    self._send_request(method, url, body, headers, encode_chunked)
  File "/usr/lib64/python3.6/http/client.py", line 1300, in _send_request
    self.endheaders(body, encode_chunked=encode_chunked)
  File "/usr/lib64/python3.6/http/client.py", line 1249, in endheaders
    self._send_output(message_body, encode_chunked=encode_chunked)
  File "/usr/lib64/python3.6/http/client.py", line 1036, in _send_output
    self.send(msg)
  File "/usr/lib64/python3.6/http/client.py", line 974, in send
    self.connect()
  File "/usr/lib64/python3.6/http/client.py", line 946, in connect
    (self.host,self.port), self.timeout, self.source_address)
  File "/usr/lib64/python3.6/socket.py", line 724, in create_connection
    raise err
  File "/usr/lib64/python3.6/socket.py", line 713, in create_connection
    sock.connect(sa)
OSError: [Errno 113] No route to host

During handling of the above exception, another exception occurred:

Traceback (most recent call last):
  File "/root/httptracker/httptracker/ec2/ec2.py", line 30, in query
    with urllib.request.urlopen(response) as data:
  File "/usr/lib64/python3.6/urllib/request.py", line 223, in urlopen
    return opener.open(url, data, timeout)
  File "/usr/lib64/python3.6/urllib/request.py", line 526, in open
    response = self._open(req, data)
  File "/usr/lib64/python3.6/urllib/request.py", line 544, in _open
    '_open', req)
  File "/usr/lib64/python3.6/urllib/request.py", line 504, in _call_chain
    result = func(*args)
  File "/usr/lib64/python3.6/urllib/request.py", line 1346, in http_open
    return self.do_open(http.client.HTTPConnection, req)
  File "/usr/lib64/python3.6/urllib/request.py", line 1320, in do_open
    raise URLError(err)
urllib.error.URLError: <urlopen error [Errno 113] No route to host>

----------------------------------------------------------------------------------------------------
[INFO] - 2020-06-21 16:16:02,917

Source log file: /usr/local/lib64/python3.6/site-packages/django/core/servers/basehttp.py line: 157

"GET /ec2/ HTTP/1.1" 200 162
----------------------------------------------------------------------------------------------------
[INFO] - 2020-06-21 16:16:05,917

Source log file: /usr/local/lib64/python3.6/site-packages/django/core/servers/basehttp.py line: 157

"GET /traceroute/ HTTP/1.1" 200 343
----------------------------------------------------------------------------------------------------
[INFO] - 2020-06-21 16:16:19,723

Source log file: /usr/local/lib64/python3.6/site-packages/django/core/servers/basehttp.py line: 157

"GET / HTTP/1.1" 200 2022
----------------------------------------------------------------------------------------------------
[INFO] - 2020-06-21 16:33:30,907

Source log file: /usr/local/lib64/python3.6/site-packages/django/utils/autoreload.py line: 222

/root/httptracker/httptracker/manage.py changed, reloading.
----------------------------------------------------------------------------------------------------
[INFO] - 2020-06-21 16:33:31,162

Source log file: /usr/local/lib64/python3.6/site-packages/django/utils/autoreload.py line: 598

Watching for file changes with StatReloader
