----------------------------------------------------------------------------------------------------
[INFO] - 2020-06-16 00:06:26,083

Source log file: /usr/local/lib64/python3.6/site-packages/django/utils/autoreload.py line: 598

Watching for file changes with StatReloader
----------------------------------------------------------------------------------------------------
[INFO] - 2020-06-16 00:06:29,608

Source log file: /usr/local/lib64/python3.6/site-packages/django/core/servers/basehttp.py line: 157

"GET / HTTP/1.1" 200 1996
----------------------------------------------------------------------------------------------------
[INFO] - 2020-06-16 00:06:29,796

Source log file: /usr/local/lib64/python3.6/site-packages/django/core/servers/basehttp.py line: 157

"GET /static/js/jquery-3.5.1.min.js HTTP/1.1" 200 89476
----------------------------------------------------------------------------------------------------
[INFO] - 2020-06-16 00:06:31,747

Source log file: /usr/local/lib64/python3.6/site-packages/django/core/servers/basehttp.py line: 157

"GET /host HTTP/1.1" 301 0
----------------------------------------------------------------------------------------------------
[INFO] - 2020-06-16 00:06:31,750

Source log file: /usr/local/lib64/python3.6/site-packages/django/core/servers/basehttp.py line: 157

"GET /ec2 HTTP/1.1" 301 0
----------------------------------------------------------------------------------------------------
[INFO] - 2020-06-16 00:06:31,757

Source log file: /usr/local/lib64/python3.6/site-packages/django/core/servers/basehttp.py line: 157

"GET /host/ HTTP/1.1" 200 79
----------------------------------------------------------------------------------------------------
[ERROR] - 2020-06-16 00:06:34,832

Source log file: /root/httptracker/httptracker/ec2/ec2.py line: 42

Traceback (most recent call last):
  File "/usr/lib64/python3.6/urllib/request.py", line 1318, in do_open
    encode_chunked=req.has_header('Transfer-encoding'))
  File "/usr/lib64/python3.6/http/client.py", line 1254, in request
    self._send_request(method, url, body, headers, encode_chunked)
  File "/usr/lib64/python3.6/http/client.py", line 1300, in _send_request
    self.endheaders(body, encode_chunked=encode_chunked)
  File "/usr/lib64/python3.6/http/client.py", line 1249, in endheaders
    self._send_output(message_body, encode_chunked=encode_chunked)
  File "/usr/lib64/python3.6/http/client.py", line 1036, in _send_output
    self.send(msg)
  File "/usr/lib64/python3.6/http/client.py", line 974, in send
    self.connect()
  File "/usr/lib64/python3.6/http/client.py", line 946, in connect
    (self.host,self.port), self.timeout, self.source_address)
  File "/usr/lib64/python3.6/socket.py", line 724, in create_connection
    raise err
  File "/usr/lib64/python3.6/socket.py", line 713, in create_connection
    sock.connect(sa)
OSError: [Errno 113] No route to host

During handling of the above exception, another exception occurred:

Traceback (most recent call last):
  File "/root/httptracker/httptracker/ec2/ec2.py", line 30, in query
    with urllib.request.urlopen(response) as data:
  File "/usr/lib64/python3.6/urllib/request.py", line 223, in urlopen
    return opener.open(url, data, timeout)
  File "/usr/lib64/python3.6/urllib/request.py", line 526, in open
    response = self._open(req, data)
  File "/usr/lib64/python3.6/urllib/request.py", line 544, in _open
    '_open', req)
  File "/usr/lib64/python3.6/urllib/request.py", line 504, in _call_chain
    result = func(*args)
  File "/usr/lib64/python3.6/urllib/request.py", line 1346, in http_open
    return self.do_open(http.client.HTTPConnection, req)
  File "/usr/lib64/python3.6/urllib/request.py", line 1320, in do_open
    raise URLError(err)
urllib.error.URLError: <urlopen error [Errno 113] No route to host>

----------------------------------------------------------------------------------------------------
[ERROR] - 2020-06-16 00:06:37,890

Source log file: /root/httptracker/httptracker/ec2/ec2.py line: 42

Traceback (most recent call last):
  File "/usr/lib64/python3.6/urllib/request.py", line 1318, in do_open
    encode_chunked=req.has_header('Transfer-encoding'))
  File "/usr/lib64/python3.6/http/client.py", line 1254, in request
    self._send_request(method, url, body, headers, encode_chunked)
  File "/usr/lib64/python3.6/http/client.py", line 1300, in _send_request
    self.endheaders(body, encode_chunked=encode_chunked)
  File "/usr/lib64/python3.6/http/client.py", line 1249, in endheaders
    self._send_output(message_body, encode_chunked=encode_chunked)
  File "/usr/lib64/python3.6/http/client.py", line 1036, in _send_output
    self.send(msg)
  File "/usr/lib64/python3.6/http/client.py", line 974, in send
    self.connect()
  File "/usr/lib64/python3.6/http/client.py", line 946, in connect
    (self.host,self.port), self.timeout, self.source_address)
  File "/usr/lib64/python3.6/socket.py", line 724, in create_connection
    raise err
  File "/usr/lib64/python3.6/socket.py", line 713, in create_connection
    sock.connect(sa)
OSError: [Errno 113] No route to host

During handling of the above exception, another exception occurred:

Traceback (most recent call last):
  File "/root/httptracker/httptracker/ec2/ec2.py", line 30, in query
    with urllib.request.urlopen(response) as data:
  File "/usr/lib64/python3.6/urllib/request.py", line 223, in urlopen
    return opener.open(url, data, timeout)
  File "/usr/lib64/python3.6/urllib/request.py", line 526, in open
    response = self._open(req, data)
  File "/usr/lib64/python3.6/urllib/request.py", line 544, in _open
    '_open', req)
  File "/usr/lib64/python3.6/urllib/request.py", line 504, in _call_chain
    result = func(*args)
  File "/usr/lib64/python3.6/urllib/request.py", line 1346, in http_open
    return self.do_open(http.client.HTTPConnection, req)
  File "/usr/lib64/python3.6/urllib/request.py", line 1320, in do_open
    raise URLError(err)
urllib.error.URLError: <urlopen error [Errno 113] No route to host>

----------------------------------------------------------------------------------------------------
[INFO] - 2020-06-16 00:06:37,893

Source log file: /usr/local/lib64/python3.6/site-packages/django/core/servers/basehttp.py line: 157

"GET /ec2/ HTTP/1.1" 200 162
----------------------------------------------------------------------------------------------------
[INFO] - 2020-06-16 00:06:56,793

Source log file: /usr/local/lib64/python3.6/site-packages/django/utils/autoreload.py line: 598

Watching for file changes with StatReloader
----------------------------------------------------------------------------------------------------
[INFO] - 2020-06-16 18:54:01,630

Source log file: /usr/local/lib64/python3.6/site-packages/django/utils/autoreload.py line: 598

Watching for file changes with StatReloader
----------------------------------------------------------------------------------------------------
[INFO] - 2020-06-16 18:54:19,879

Source log file: /usr/local/lib64/python3.6/site-packages/django/core/servers/basehttp.py line: 157

"GET / HTTP/1.1" 200 1996
----------------------------------------------------------------------------------------------------
[INFO] - 2020-06-16 18:54:19,990

Source log file: /usr/local/lib64/python3.6/site-packages/django/core/servers/basehttp.py line: 157

"GET /static/js/jquery-3.5.1.min.js HTTP/1.1" 200 89476
----------------------------------------------------------------------------------------------------
[WARNING] - 2020-06-16 18:54:20,239

Source log file: /usr/local/lib64/python3.6/site-packages/django/utils/log.py line: 228

Not Found: /favicon.ico
----------------------------------------------------------------------------------------------------
[WARNING] - 2020-06-16 18:54:20,240

Source log file: /usr/local/lib64/python3.6/site-packages/django/core/servers/basehttp.py line: 157

"GET /favicon.ico HTTP/1.1" 404 2196
----------------------------------------------------------------------------------------------------
[INFO] - 2020-06-16 18:54:21,315

Source log file: /usr/local/lib64/python3.6/site-packages/django/core/servers/basehttp.py line: 157

"GET /host/ HTTP/1.1" 200 79
----------------------------------------------------------------------------------------------------
[ERROR] - 2020-06-16 18:54:24,374

Source log file: /root/httptracker/httptracker/ec2/ec2.py line: 42

Traceback (most recent call last):
  File "/usr/lib64/python3.6/urllib/request.py", line 1318, in do_open
    encode_chunked=req.has_header('Transfer-encoding'))
  File "/usr/lib64/python3.6/http/client.py", line 1254, in request
    self._send_request(method, url, body, headers, encode_chunked)
  File "/usr/lib64/python3.6/http/client.py", line 1300, in _send_request
    self.endheaders(body, encode_chunked=encode_chunked)
  File "/usr/lib64/python3.6/http/client.py", line 1249, in endheaders
    self._send_output(message_body, encode_chunked=encode_chunked)
  File "/usr/lib64/python3.6/http/client.py", line 1036, in _send_output
    self.send(msg)
  File "/usr/lib64/python3.6/http/client.py", line 974, in send
    self.connect()
  File "/usr/lib64/python3.6/http/client.py", line 946, in connect
    (self.host,self.port), self.timeout, self.source_address)
  File "/usr/lib64/python3.6/socket.py", line 724, in create_connection
    raise err
  File "/usr/lib64/python3.6/socket.py", line 713, in create_connection
    sock.connect(sa)
OSError: [Errno 113] No route to host

During handling of the above exception, another exception occurred:

Traceback (most recent call last):
  File "/root/httptracker/httptracker/ec2/ec2.py", line 30, in query
    with urllib.request.urlopen(response) as data:
  File "/usr/lib64/python3.6/urllib/request.py", line 223, in urlopen
    return opener.open(url, data, timeout)
  File "/usr/lib64/python3.6/urllib/request.py", line 526, in open
    response = self._open(req, data)
  File "/usr/lib64/python3.6/urllib/request.py", line 544, in _open
    '_open', req)
  File "/usr/lib64/python3.6/urllib/request.py", line 504, in _call_chain
    result = func(*args)
  File "/usr/lib64/python3.6/urllib/request.py", line 1346, in http_open
    return self.do_open(http.client.HTTPConnection, req)
  File "/usr/lib64/python3.6/urllib/request.py", line 1320, in do_open
    raise URLError(err)
urllib.error.URLError: <urlopen error [Errno 113] No route to host>

----------------------------------------------------------------------------------------------------
[ERROR] - 2020-06-16 18:54:27,450

Source log file: /root/httptracker/httptracker/ec2/ec2.py line: 42

Traceback (most recent call last):
  File "/usr/lib64/python3.6/urllib/request.py", line 1318, in do_open
    encode_chunked=req.has_header('Transfer-encoding'))
  File "/usr/lib64/python3.6/http/client.py", line 1254, in request
    self._send_request(method, url, body, headers, encode_chunked)
  File "/usr/lib64/python3.6/http/client.py", line 1300, in _send_request
    self.endheaders(body, encode_chunked=encode_chunked)
  File "/usr/lib64/python3.6/http/client.py", line 1249, in endheaders
    self._send_output(message_body, encode_chunked=encode_chunked)
  File "/usr/lib64/python3.6/http/client.py", line 1036, in _send_output
    self.send(msg)
  File "/usr/lib64/python3.6/http/client.py", line 974, in send
    self.connect()
  File "/usr/lib64/python3.6/http/client.py", line 946, in connect
    (self.host,self.port), self.timeout, self.source_address)
  File "/usr/lib64/python3.6/socket.py", line 724, in create_connection
    raise err
  File "/usr/lib64/python3.6/socket.py", line 713, in create_connection
    sock.connect(sa)
OSError: [Errno 113] No route to host

During handling of the above exception, another exception occurred:

Traceback (most recent call last):
  File "/root/httptracker/httptracker/ec2/ec2.py", line 30, in query
    with urllib.request.urlopen(response) as data:
  File "/usr/lib64/python3.6/urllib/request.py", line 223, in urlopen
    return opener.open(url, data, timeout)
  File "/usr/lib64/python3.6/urllib/request.py", line 526, in open
    response = self._open(req, data)
  File "/usr/lib64/python3.6/urllib/request.py", line 544, in _open
    '_open', req)
  File "/usr/lib64/python3.6/urllib/request.py", line 504, in _call_chain
    result = func(*args)
  File "/usr/lib64/python3.6/urllib/request.py", line 1346, in http_open
    return self.do_open(http.client.HTTPConnection, req)
  File "/usr/lib64/python3.6/urllib/request.py", line 1320, in do_open
    raise URLError(err)
urllib.error.URLError: <urlopen error [Errno 113] No route to host>

----------------------------------------------------------------------------------------------------
[INFO] - 2020-06-16 18:54:27,452

Source log file: /usr/local/lib64/python3.6/site-packages/django/core/servers/basehttp.py line: 157

"GET /ec2/ HTTP/1.1" 200 162
----------------------------------------------------------------------------------------------------
[INFO] - 2020-06-16 18:55:39,307

Source log file: /usr/local/lib64/python3.6/site-packages/django/core/servers/basehttp.py line: 157

"GET / HTTP/1.1" 200 2000
----------------------------------------------------------------------------------------------------
[INFO] - 2020-06-16 18:55:39,337

Source log file: /usr/local/lib64/python3.6/site-packages/django/core/servers/basehttp.py line: 157

"GET /static/js/jquery-3.5.1.min.js HTTP/1.1" 200 89476
----------------------------------------------------------------------------------------------------
[INFO] - 2020-06-16 18:55:40,835

Source log file: /usr/local/lib64/python3.6/site-packages/django/core/servers/basehttp.py line: 157

"GET /host HTTP/1.1" 301 0
----------------------------------------------------------------------------------------------------
[INFO] - 2020-06-16 18:55:40,837

Source log file: /usr/local/lib64/python3.6/site-packages/django/core/servers/basehttp.py line: 157

"GET /ec2 HTTP/1.1" 301 0
----------------------------------------------------------------------------------------------------
[INFO] - 2020-06-16 18:55:40,843

Source log file: /usr/local/lib64/python3.6/site-packages/django/core/servers/basehttp.py line: 157

"GET /host/ HTTP/1.1" 200 79
----------------------------------------------------------------------------------------------------
[ERROR] - 2020-06-16 18:55:43,892

Source log file: /root/httptracker/httptracker/ec2/ec2.py line: 42

Traceback (most recent call last):
  File "/usr/lib64/python3.6/urllib/request.py", line 1318, in do_open
    encode_chunked=req.has_header('Transfer-encoding'))
  File "/usr/lib64/python3.6/http/client.py", line 1254, in request
    self._send_request(method, url, body, headers, encode_chunked)
  File "/usr/lib64/python3.6/http/client.py", line 1300, in _send_request
    self.endheaders(body, encode_chunked=encode_chunked)
  File "/usr/lib64/python3.6/http/client.py", line 1249, in endheaders
    self._send_output(message_body, encode_chunked=encode_chunked)
  File "/usr/lib64/python3.6/http/client.py", line 1036, in _send_output
    self.send(msg)
  File "/usr/lib64/python3.6/http/client.py", line 974, in send
    self.connect()
  File "/usr/lib64/python3.6/http/client.py", line 946, in connect
    (self.host,self.port), self.timeout, self.source_address)
  File "/usr/lib64/python3.6/socket.py", line 724, in create_connection
    raise err
  File "/usr/lib64/python3.6/socket.py", line 713, in create_connection
    sock.connect(sa)
OSError: [Errno 113] No route to host

During handling of the above exception, another exception occurred:

Traceback (most recent call last):
  File "/root/httptracker/httptracker/ec2/ec2.py", line 30, in query
    with urllib.request.urlopen(response) as data:
  File "/usr/lib64/python3.6/urllib/request.py", line 223, in urlopen
    return opener.open(url, data, timeout)
  File "/usr/lib64/python3.6/urllib/request.py", line 526, in open
    response = self._open(req, data)
  File "/usr/lib64/python3.6/urllib/request.py", line 544, in _open
    '_open', req)
  File "/usr/lib64/python3.6/urllib/request.py", line 504, in _call_chain
    result = func(*args)
  File "/usr/lib64/python3.6/urllib/request.py", line 1346, in http_open
    return self.do_open(http.client.HTTPConnection, req)
  File "/usr/lib64/python3.6/urllib/request.py", line 1320, in do_open
    raise URLError(err)
urllib.error.URLError: <urlopen error [Errno 113] No route to host>

----------------------------------------------------------------------------------------------------
[ERROR] - 2020-06-16 18:55:46,964

Source log file: /root/httptracker/httptracker/ec2/ec2.py line: 42

Traceback (most recent call last):
  File "/usr/lib64/python3.6/urllib/request.py", line 1318, in do_open
    encode_chunked=req.has_header('Transfer-encoding'))
  File "/usr/lib64/python3.6/http/client.py", line 1254, in request
    self._send_request(method, url, body, headers, encode_chunked)
  File "/usr/lib64/python3.6/http/client.py", line 1300, in _send_request
    self.endheaders(body, encode_chunked=encode_chunked)
  File "/usr/lib64/python3.6/http/client.py", line 1249, in endheaders
    self._send_output(message_body, encode_chunked=encode_chunked)
  File "/usr/lib64/python3.6/http/client.py", line 1036, in _send_output
    self.send(msg)
  File "/usr/lib64/python3.6/http/client.py", line 974, in send
    self.connect()
  File "/usr/lib64/python3.6/http/client.py", line 946, in connect
    (self.host,self.port), self.timeout, self.source_address)
  File "/usr/lib64/python3.6/socket.py", line 724, in create_connection
    raise err
  File "/usr/lib64/python3.6/socket.py", line 713, in create_connection
    sock.connect(sa)
OSError: [Errno 113] No route to host

During handling of the above exception, another exception occurred:

Traceback (most recent call last):
  File "/root/httptracker/httptracker/ec2/ec2.py", line 30, in query
    with urllib.request.urlopen(response) as data:
  File "/usr/lib64/python3.6/urllib/request.py", line 223, in urlopen
    return opener.open(url, data, timeout)
  File "/usr/lib64/python3.6/urllib/request.py", line 526, in open
    response = self._open(req, data)
  File "/usr/lib64/python3.6/urllib/request.py", line 544, in _open
    '_open', req)
  File "/usr/lib64/python3.6/urllib/request.py", line 504, in _call_chain
    result = func(*args)
  File "/usr/lib64/python3.6/urllib/request.py", line 1346, in http_open
    return self.do_open(http.client.HTTPConnection, req)
  File "/usr/lib64/python3.6/urllib/request.py", line 1320, in do_open
    raise URLError(err)
urllib.error.URLError: <urlopen error [Errno 113] No route to host>

----------------------------------------------------------------------------------------------------
[INFO] - 2020-06-16 18:55:46,965

Source log file: /usr/local/lib64/python3.6/site-packages/django/core/servers/basehttp.py line: 157

"GET /ec2/ HTTP/1.1" 200 162
----------------------------------------------------------------------------------------------------
[INFO] - 2020-06-16 19:02:50,616

Source log file: /usr/local/lib64/python3.6/site-packages/django/utils/autoreload.py line: 222

/root/httptracker/httptracker/httptracker/urls.py changed, reloading.
----------------------------------------------------------------------------------------------------
[INFO] - 2020-06-16 19:02:50,931

Source log file: /usr/local/lib64/python3.6/site-packages/django/utils/autoreload.py line: 598

Watching for file changes with StatReloader
----------------------------------------------------------------------------------------------------
[INFO] - 2020-06-16 19:03:50,582

Source log file: /usr/local/lib64/python3.6/site-packages/django/utils/autoreload.py line: 222

/root/httptracker/httptracker/httptracker/settings.py changed, reloading.
----------------------------------------------------------------------------------------------------
[INFO] - 2020-06-16 19:03:50,949

Source log file: /usr/local/lib64/python3.6/site-packages/django/utils/autoreload.py line: 598

Watching for file changes with StatReloader
----------------------------------------------------------------------------------------------------
[INFO] - 2020-06-16 23:23:21,603

Source log file: /usr/local/lib64/python3.6/site-packages/django/utils/autoreload.py line: 222

/root/httptracker/httptracker/host/views.py changed, reloading.
----------------------------------------------------------------------------------------------------
[INFO] - 2020-06-16 23:23:21,923

Source log file: /usr/local/lib64/python3.6/site-packages/django/utils/autoreload.py line: 598

Watching for file changes with StatReloader
----------------------------------------------------------------------------------------------------
[INFO] - 2020-06-16 23:23:26,864

Source log file: /usr/local/lib64/python3.6/site-packages/django/core/servers/basehttp.py line: 157

"GET / HTTP/1.1" 200 2000
----------------------------------------------------------------------------------------------------
[INFO] - 2020-06-16 23:23:27,015

Source log file: /usr/local/lib64/python3.6/site-packages/django/core/servers/basehttp.py line: 157

"GET /static/js/jquery-3.5.1.min.js HTTP/1.1" 200 89476
----------------------------------------------------------------------------------------------------
[INFO] - 2020-06-16 23:23:34,908

Source log file: /usr/local/lib64/python3.6/site-packages/django/core/servers/basehttp.py line: 157

"GET /host HTTP/1.1" 301 0
----------------------------------------------------------------------------------------------------
[INFO] - 2020-06-16 23:23:34,910

Source log file: /usr/local/lib64/python3.6/site-packages/django/core/servers/basehttp.py line: 157

"GET /ec2 HTTP/1.1" 301 0
----------------------------------------------------------------------------------------------------
[INFO] - 2020-06-16 23:23:34,918

Source log file: /usr/local/lib64/python3.6/site-packages/django/core/servers/basehttp.py line: 157

"GET /host/ HTTP/1.1" 200 79
----------------------------------------------------------------------------------------------------
[ERROR] - 2020-06-16 23:23:37,973

Source log file: /root/httptracker/httptracker/ec2/ec2.py line: 42

Traceback (most recent call last):
  File "/usr/lib64/python3.6/urllib/request.py", line 1318, in do_open
    encode_chunked=req.has_header('Transfer-encoding'))
  File "/usr/lib64/python3.6/http/client.py", line 1254, in request
    self._send_request(method, url, body, headers, encode_chunked)
  File "/usr/lib64/python3.6/http/client.py", line 1300, in _send_request
    self.endheaders(body, encode_chunked=encode_chunked)
  File "/usr/lib64/python3.6/http/client.py", line 1249, in endheaders
    self._send_output(message_body, encode_chunked=encode_chunked)
  File "/usr/lib64/python3.6/http/client.py", line 1036, in _send_output
    self.send(msg)
  File "/usr/lib64/python3.6/http/client.py", line 974, in send
    self.connect()
  File "/usr/lib64/python3.6/http/client.py", line 946, in connect
    (self.host,self.port), self.timeout, self.source_address)
  File "/usr/lib64/python3.6/socket.py", line 724, in create_connection
    raise err
  File "/usr/lib64/python3.6/socket.py", line 713, in create_connection
    sock.connect(sa)
OSError: [Errno 113] No route to host

During handling of the above exception, another exception occurred:

Traceback (most recent call last):
  File "/root/httptracker/httptracker/ec2/ec2.py", line 30, in query
    with urllib.request.urlopen(response) as data:
  File "/usr/lib64/python3.6/urllib/request.py", line 223, in urlopen
    return opener.open(url, data, timeout)
  File "/usr/lib64/python3.6/urllib/request.py", line 526, in open
    response = self._open(req, data)
  File "/usr/lib64/python3.6/urllib/request.py", line 544, in _open
    '_open', req)
  File "/usr/lib64/python3.6/urllib/request.py", line 504, in _call_chain
    result = func(*args)
  File "/usr/lib64/python3.6/urllib/request.py", line 1346, in http_open
    return self.do_open(http.client.HTTPConnection, req)
  File "/usr/lib64/python3.6/urllib/request.py", line 1320, in do_open
    raise URLError(err)
urllib.error.URLError: <urlopen error [Errno 113] No route to host>

----------------------------------------------------------------------------------------------------
[ERROR] - 2020-06-16 23:23:41,044

Source log file: /root/httptracker/httptracker/ec2/ec2.py line: 42

Traceback (most recent call last):
  File "/usr/lib64/python3.6/urllib/request.py", line 1318, in do_open
    encode_chunked=req.has_header('Transfer-encoding'))
  File "/usr/lib64/python3.6/http/client.py", line 1254, in request
    self._send_request(method, url, body, headers, encode_chunked)
  File "/usr/lib64/python3.6/http/client.py", line 1300, in _send_request
    self.endheaders(body, encode_chunked=encode_chunked)
  File "/usr/lib64/python3.6/http/client.py", line 1249, in endheaders
    self._send_output(message_body, encode_chunked=encode_chunked)
  File "/usr/lib64/python3.6/http/client.py", line 1036, in _send_output
    self.send(msg)
  File "/usr/lib64/python3.6/http/client.py", line 974, in send
    self.connect()
  File "/usr/lib64/python3.6/http/client.py", line 946, in connect
    (self.host,self.port), self.timeout, self.source_address)
  File "/usr/lib64/python3.6/socket.py", line 724, in create_connection
    raise err
  File "/usr/lib64/python3.6/socket.py", line 713, in create_connection
    sock.connect(sa)
OSError: [Errno 113] No route to host

During handling of the above exception, another exception occurred:

Traceback (most recent call last):
  File "/root/httptracker/httptracker/ec2/ec2.py", line 30, in query
    with urllib.request.urlopen(response) as data:
  File "/usr/lib64/python3.6/urllib/request.py", line 223, in urlopen
    return opener.open(url, data, timeout)
  File "/usr/lib64/python3.6/urllib/request.py", line 526, in open
    response = self._open(req, data)
  File "/usr/lib64/python3.6/urllib/request.py", line 544, in _open
    '_open', req)
  File "/usr/lib64/python3.6/urllib/request.py", line 504, in _call_chain
    result = func(*args)
  File "/usr/lib64/python3.6/urllib/request.py", line 1346, in http_open
    return self.do_open(http.client.HTTPConnection, req)
  File "/usr/lib64/python3.6/urllib/request.py", line 1320, in do_open
    raise URLError(err)
urllib.error.URLError: <urlopen error [Errno 113] No route to host>

----------------------------------------------------------------------------------------------------
[INFO] - 2020-06-16 23:23:41,045

Source log file: /usr/local/lib64/python3.6/site-packages/django/core/servers/basehttp.py line: 157

"GET /ec2/ HTTP/1.1" 200 162
----------------------------------------------------------------------------------------------------
[INFO] - 2020-06-16 23:25:40,032

Source log file: /usr/local/lib64/python3.6/site-packages/django/utils/autoreload.py line: 222

/root/httptracker/httptracker/host/views.py changed, reloading.
----------------------------------------------------------------------------------------------------
[INFO] - 2020-06-16 23:25:40,343

Source log file: /usr/local/lib64/python3.6/site-packages/django/utils/autoreload.py line: 598

Watching for file changes with StatReloader
----------------------------------------------------------------------------------------------------
[INFO] - 2020-06-16 23:25:46,137

Source log file: /usr/local/lib64/python3.6/site-packages/django/core/servers/basehttp.py line: 157

"GET / HTTP/1.1" 200 2000
----------------------------------------------------------------------------------------------------
[INFO] - 2020-06-16 23:25:46,160

Source log file: /usr/local/lib64/python3.6/site-packages/django/core/servers/basehttp.py line: 157

"GET /static/js/jquery-3.5.1.min.js HTTP/1.1" 200 89476
----------------------------------------------------------------------------------------------------
[INFO] - 2020-06-16 23:25:47,867

Source log file: /usr/local/lib64/python3.6/site-packages/django/core/servers/basehttp.py line: 157

"GET /host HTTP/1.1" 301 0
----------------------------------------------------------------------------------------------------
[INFO] - 2020-06-16 23:25:47,869

Source log file: /usr/local/lib64/python3.6/site-packages/django/core/servers/basehttp.py line: 157

"GET /ec2 HTTP/1.1" 301 0
----------------------------------------------------------------------------------------------------
[INFO] - 2020-06-16 23:25:47,874

Source log file: /root/httptracker/httptracker/host/views.py line: 16

<rest_framework.request.Request object at 0x7f815c6b85f8>
----------------------------------------------------------------------------------------------------
[INFO] - 2020-06-16 23:25:47,878

Source log file: /usr/local/lib64/python3.6/site-packages/django/core/servers/basehttp.py line: 157

"GET /host/ HTTP/1.1" 200 79
----------------------------------------------------------------------------------------------------
[ERROR] - 2020-06-16 23:25:50,933

Source log file: /root/httptracker/httptracker/ec2/ec2.py line: 42

Traceback (most recent call last):
  File "/usr/lib64/python3.6/urllib/request.py", line 1318, in do_open
    encode_chunked=req.has_header('Transfer-encoding'))
  File "/usr/lib64/python3.6/http/client.py", line 1254, in request
    self._send_request(method, url, body, headers, encode_chunked)
  File "/usr/lib64/python3.6/http/client.py", line 1300, in _send_request
    self.endheaders(body, encode_chunked=encode_chunked)
  File "/usr/lib64/python3.6/http/client.py", line 1249, in endheaders
    self._send_output(message_body, encode_chunked=encode_chunked)
  File "/usr/lib64/python3.6/http/client.py", line 1036, in _send_output
    self.send(msg)
  File "/usr/lib64/python3.6/http/client.py", line 974, in send
    self.connect()
  File "/usr/lib64/python3.6/http/client.py", line 946, in connect
    (self.host,self.port), self.timeout, self.source_address)
  File "/usr/lib64/python3.6/socket.py", line 724, in create_connection
    raise err
  File "/usr/lib64/python3.6/socket.py", line 713, in create_connection
    sock.connect(sa)
OSError: [Errno 113] No route to host

During handling of the above exception, another exception occurred:

Traceback (most recent call last):
  File "/root/httptracker/httptracker/ec2/ec2.py", line 30, in query
    with urllib.request.urlopen(response) as data:
  File "/usr/lib64/python3.6/urllib/request.py", line 223, in urlopen
    return opener.open(url, data, timeout)
  File "/usr/lib64/python3.6/urllib/request.py", line 526, in open
    response = self._open(req, data)
  File "/usr/lib64/python3.6/urllib/request.py", line 544, in _open
    '_open', req)
  File "/usr/lib64/python3.6/urllib/request.py", line 504, in _call_chain
    result = func(*args)
  File "/usr/lib64/python3.6/urllib/request.py", line 1346, in http_open
    return self.do_open(http.client.HTTPConnection, req)
  File "/usr/lib64/python3.6/urllib/request.py", line 1320, in do_open
    raise URLError(err)
urllib.error.URLError: <urlopen error [Errno 113] No route to host>

----------------------------------------------------------------------------------------------------
[ERROR] - 2020-06-16 23:25:54,004

Source log file: /root/httptracker/httptracker/ec2/ec2.py line: 42

Traceback (most recent call last):
  File "/usr/lib64/python3.6/urllib/request.py", line 1318, in do_open
    encode_chunked=req.has_header('Transfer-encoding'))
  File "/usr/lib64/python3.6/http/client.py", line 1254, in request
    self._send_request(method, url, body, headers, encode_chunked)
  File "/usr/lib64/python3.6/http/client.py", line 1300, in _send_request
    self.endheaders(body, encode_chunked=encode_chunked)
  File "/usr/lib64/python3.6/http/client.py", line 1249, in endheaders
    self._send_output(message_body, encode_chunked=encode_chunked)
  File "/usr/lib64/python3.6/http/client.py", line 1036, in _send_output
    self.send(msg)
  File "/usr/lib64/python3.6/http/client.py", line 974, in send
    self.connect()
  File "/usr/lib64/python3.6/http/client.py", line 946, in connect
    (self.host,self.port), self.timeout, self.source_address)
  File "/usr/lib64/python3.6/socket.py", line 724, in create_connection
    raise err
  File "/usr/lib64/python3.6/socket.py", line 713, in create_connection
    sock.connect(sa)
OSError: [Errno 113] No route to host

During handling of the above exception, another exception occurred:

Traceback (most recent call last):
  File "/root/httptracker/httptracker/ec2/ec2.py", line 30, in query
    with urllib.request.urlopen(response) as data:
  File "/usr/lib64/python3.6/urllib/request.py", line 223, in urlopen
    return opener.open(url, data, timeout)
  File "/usr/lib64/python3.6/urllib/request.py", line 526, in open
    response = self._open(req, data)
  File "/usr/lib64/python3.6/urllib/request.py", line 544, in _open
    '_open', req)
  File "/usr/lib64/python3.6/urllib/request.py", line 504, in _call_chain
    result = func(*args)
  File "/usr/lib64/python3.6/urllib/request.py", line 1346, in http_open
    return self.do_open(http.client.HTTPConnection, req)
  File "/usr/lib64/python3.6/urllib/request.py", line 1320, in do_open
    raise URLError(err)
urllib.error.URLError: <urlopen error [Errno 113] No route to host>

----------------------------------------------------------------------------------------------------
[INFO] - 2020-06-16 23:25:54,004

Source log file: /usr/local/lib64/python3.6/site-packages/django/core/servers/basehttp.py line: 157

"GET /ec2/ HTTP/1.1" 200 162
----------------------------------------------------------------------------------------------------
[INFO] - 2020-06-16 23:27:12,156

Source log file: /usr/local/lib64/python3.6/site-packages/django/utils/autoreload.py line: 222

/root/httptracker/httptracker/host/views.py changed, reloading.
----------------------------------------------------------------------------------------------------
[INFO] - 2020-06-16 23:27:12,463

Source log file: /usr/local/lib64/python3.6/site-packages/django/utils/autoreload.py line: 598

Watching for file changes with StatReloader
----------------------------------------------------------------------------------------------------
[INFO] - 2020-06-16 23:27:16,423

Source log file: /usr/local/lib64/python3.6/site-packages/django/core/servers/basehttp.py line: 157

"GET /host HTTP/1.1" 301 0
----------------------------------------------------------------------------------------------------
[INFO] - 2020-06-16 23:27:16,424

Source log file: /usr/local/lib64/python3.6/site-packages/django/core/servers/basehttp.py line: 157

"GET /ec2 HTTP/1.1" 301 0
----------------------------------------------------------------------------------------------------
[INFO] - 2020-06-16 23:27:16,430

Source log file: /root/httptracker/httptracker/host/views.py line: 16

{}
----------------------------------------------------------------------------------------------------
[INFO] - 2020-06-16 23:27:16,433

Source log file: /usr/local/lib64/python3.6/site-packages/django/core/servers/basehttp.py line: 157

"GET /host/ HTTP/1.1" 200 79
----------------------------------------------------------------------------------------------------
[ERROR] - 2020-06-16 23:27:19,510

Source log file: /root/httptracker/httptracker/ec2/ec2.py line: 42

Traceback (most recent call last):
  File "/usr/lib64/python3.6/urllib/request.py", line 1318, in do_open
    encode_chunked=req.has_header('Transfer-encoding'))
  File "/usr/lib64/python3.6/http/client.py", line 1254, in request
    self._send_request(method, url, body, headers, encode_chunked)
  File "/usr/lib64/python3.6/http/client.py", line 1300, in _send_request
    self.endheaders(body, encode_chunked=encode_chunked)
  File "/usr/lib64/python3.6/http/client.py", line 1249, in endheaders
    self._send_output(message_body, encode_chunked=encode_chunked)
  File "/usr/lib64/python3.6/http/client.py", line 1036, in _send_output
    self.send(msg)
  File "/usr/lib64/python3.6/http/client.py", line 974, in send
    self.connect()
  File "/usr/lib64/python3.6/http/client.py", line 946, in connect
    (self.host,self.port), self.timeout, self.source_address)
  File "/usr/lib64/python3.6/socket.py", line 724, in create_connection
    raise err
  File "/usr/lib64/python3.6/socket.py", line 713, in create_connection
    sock.connect(sa)
OSError: [Errno 113] No route to host

During handling of the above exception, another exception occurred:

Traceback (most recent call last):
  File "/root/httptracker/httptracker/ec2/ec2.py", line 30, in query
    with urllib.request.urlopen(response) as data:
  File "/usr/lib64/python3.6/urllib/request.py", line 223, in urlopen
    return opener.open(url, data, timeout)
  File "/usr/lib64/python3.6/urllib/request.py", line 526, in open
    response = self._open(req, data)
  File "/usr/lib64/python3.6/urllib/request.py", line 544, in _open
    '_open', req)
  File "/usr/lib64/python3.6/urllib/request.py", line 504, in _call_chain
    result = func(*args)
  File "/usr/lib64/python3.6/urllib/request.py", line 1346, in http_open
    return self.do_open(http.client.HTTPConnection, req)
  File "/usr/lib64/python3.6/urllib/request.py", line 1320, in do_open
    raise URLError(err)
urllib.error.URLError: <urlopen error [Errno 113] No route to host>

----------------------------------------------------------------------------------------------------
[ERROR] - 2020-06-16 23:27:22,584

Source log file: /root/httptracker/httptracker/ec2/ec2.py line: 42

Traceback (most recent call last):
  File "/usr/lib64/python3.6/urllib/request.py", line 1318, in do_open
    encode_chunked=req.has_header('Transfer-encoding'))
  File "/usr/lib64/python3.6/http/client.py", line 1254, in request
    self._send_request(method, url, body, headers, encode_chunked)
  File "/usr/lib64/python3.6/http/client.py", line 1300, in _send_request
    self.endheaders(body, encode_chunked=encode_chunked)
  File "/usr/lib64/python3.6/http/client.py", line 1249, in endheaders
    self._send_output(message_body, encode_chunked=encode_chunked)
  File "/usr/lib64/python3.6/http/client.py", line 1036, in _send_output
    self.send(msg)
  File "/usr/lib64/python3.6/http/client.py", line 974, in send
    self.connect()
  File "/usr/lib64/python3.6/http/client.py", line 946, in connect
    (self.host,self.port), self.timeout, self.source_address)
  File "/usr/lib64/python3.6/socket.py", line 724, in create_connection
    raise err
  File "/usr/lib64/python3.6/socket.py", line 713, in create_connection
    sock.connect(sa)
OSError: [Errno 113] No route to host

During handling of the above exception, another exception occurred:

Traceback (most recent call last):
  File "/root/httptracker/httptracker/ec2/ec2.py", line 30, in query
    with urllib.request.urlopen(response) as data:
  File "/usr/lib64/python3.6/urllib/request.py", line 223, in urlopen
    return opener.open(url, data, timeout)
  File "/usr/lib64/python3.6/urllib/request.py", line 526, in open
    response = self._open(req, data)
  File "/usr/lib64/python3.6/urllib/request.py", line 544, in _open
    '_open', req)
  File "/usr/lib64/python3.6/urllib/request.py", line 504, in _call_chain
    result = func(*args)
  File "/usr/lib64/python3.6/urllib/request.py", line 1346, in http_open
    return self.do_open(http.client.HTTPConnection, req)
  File "/usr/lib64/python3.6/urllib/request.py", line 1320, in do_open
    raise URLError(err)
urllib.error.URLError: <urlopen error [Errno 113] No route to host>

----------------------------------------------------------------------------------------------------
[INFO] - 2020-06-16 23:27:22,585

Source log file: /usr/local/lib64/python3.6/site-packages/django/core/servers/basehttp.py line: 157

"GET /ec2/ HTTP/1.1" 200 162
----------------------------------------------------------------------------------------------------
[INFO] - 2020-06-16 23:33:26,875

Source log file: /usr/local/lib64/python3.6/site-packages/django/utils/autoreload.py line: 222

/root/httptracker/httptracker/host/views.py changed, reloading.
----------------------------------------------------------------------------------------------------
[INFO] - 2020-06-16 23:33:27,166

Source log file: /usr/local/lib64/python3.6/site-packages/django/utils/autoreload.py line: 598

Watching for file changes with StatReloader
----------------------------------------------------------------------------------------------------
[INFO] - 2020-06-16 23:33:30,194

Source log file: /usr/local/lib64/python3.6/site-packages/django/core/servers/basehttp.py line: 157

"GET /host HTTP/1.1" 301 0
----------------------------------------------------------------------------------------------------
[INFO] - 2020-06-16 23:33:30,196

Source log file: /usr/local/lib64/python3.6/site-packages/django/core/servers/basehttp.py line: 157

"GET /ec2 HTTP/1.1" 301 0
----------------------------------------------------------------------------------------------------
[ERROR] - 2020-06-16 23:33:30,212

Source log file: /root/httptracker/httptracker/host/views.py line: 22

Traceback (most recent call last):
  File "/usr/local/lib/python3.6/site-packages/rest_framework/request.py", line 409, in __getattr__
    return getattr(self._request, attr)
AttributeError: 'WSGIRequest' object has no attribute 'remote_addr'

During handling of the above exception, another exception occurred:

Traceback (most recent call last):
  File "/root/httptracker/httptracker/host/views.py", line 16, in get
    logger.info(request.environ.get("HTTP_X_REAL_IP", request.remote_addr))
  File "/usr/local/lib/python3.6/site-packages/rest_framework/request.py", line 411, in __getattr__
    return self.__getattribute__(attr)
AttributeError: 'Request' object has no attribute 'remote_addr'

----------------------------------------------------------------------------------------------------
[ERROR] - 2020-06-16 23:33:30,232

Source log file: /usr/local/lib64/python3.6/site-packages/django/utils/log.py line: 228

Internal Server Error: /host/
Traceback (most recent call last):
  File "/usr/local/lib64/python3.6/site-packages/django/core/handlers/exception.py", line 34, in inner
    response = get_response(request)
  File "/usr/local/lib64/python3.6/site-packages/django/core/handlers/base.py", line 115, in _get_response
    response = self.process_exception_by_middleware(e, request)
  File "/usr/local/lib64/python3.6/site-packages/django/core/handlers/base.py", line 113, in _get_response
    response = wrapped_callback(request, *callback_args, **callback_kwargs)
  File "/usr/local/lib64/python3.6/site-packages/django/views/decorators/csrf.py", line 54, in wrapped_view
    return view_func(*args, **kwargs)
  File "/usr/local/lib64/python3.6/site-packages/django/views/generic/base.py", line 71, in view
    return self.dispatch(request, *args, **kwargs)
  File "/usr/local/lib/python3.6/site-packages/rest_framework/views.py", line 507, in dispatch
    self.response = self.finalize_response(request, response, *args, **kwargs)
  File "/usr/local/lib/python3.6/site-packages/rest_framework/views.py", line 422, in finalize_response
    % type(response)
AssertionError: Expected a `Response`, `HttpResponse` or `HttpStreamingResponse` to be returned from the view, but received a `<class 'NoneType'>`
----------------------------------------------------------------------------------------------------
[ERROR] - 2020-06-16 23:33:30,233

Source log file: /usr/local/lib64/python3.6/site-packages/django/core/servers/basehttp.py line: 157

"GET /host/ HTTP/1.1" 500 17177
----------------------------------------------------------------------------------------------------
[ERROR] - 2020-06-16 23:33:33,273

Source log file: /root/httptracker/httptracker/ec2/ec2.py line: 42

Traceback (most recent call last):
  File "/usr/lib64/python3.6/urllib/request.py", line 1318, in do_open
    encode_chunked=req.has_header('Transfer-encoding'))
  File "/usr/lib64/python3.6/http/client.py", line 1254, in request
    self._send_request(method, url, body, headers, encode_chunked)
  File "/usr/lib64/python3.6/http/client.py", line 1300, in _send_request
    self.endheaders(body, encode_chunked=encode_chunked)
  File "/usr/lib64/python3.6/http/client.py", line 1249, in endheaders
    self._send_output(message_body, encode_chunked=encode_chunked)
  File "/usr/lib64/python3.6/http/client.py", line 1036, in _send_output
    self.send(msg)
  File "/usr/lib64/python3.6/http/client.py", line 974, in send
    self.connect()
  File "/usr/lib64/python3.6/http/client.py", line 946, in connect
    (self.host,self.port), self.timeout, self.source_address)
  File "/usr/lib64/python3.6/socket.py", line 724, in create_connection
    raise err
  File "/usr/lib64/python3.6/socket.py", line 713, in create_connection
    sock.connect(sa)
OSError: [Errno 113] No route to host

During handling of the above exception, another exception occurred:

Traceback (most recent call last):
  File "/root/httptracker/httptracker/ec2/ec2.py", line 30, in query
    with urllib.request.urlopen(response) as data:
  File "/usr/lib64/python3.6/urllib/request.py", line 223, in urlopen
    return opener.open(url, data, timeout)
  File "/usr/lib64/python3.6/urllib/request.py", line 526, in open
    response = self._open(req, data)
  File "/usr/lib64/python3.6/urllib/request.py", line 544, in _open
    '_open', req)
  File "/usr/lib64/python3.6/urllib/request.py", line 504, in _call_chain
    result = func(*args)
  File "/usr/lib64/python3.6/urllib/request.py", line 1346, in http_open
    return self.do_open(http.client.HTTPConnection, req)
  File "/usr/lib64/python3.6/urllib/request.py", line 1320, in do_open
    raise URLError(err)
urllib.error.URLError: <urlopen error [Errno 113] No route to host>

----------------------------------------------------------------------------------------------------
[ERROR] - 2020-06-16 23:33:36,342

Source log file: /root/httptracker/httptracker/ec2/ec2.py line: 42

Traceback (most recent call last):
  File "/usr/lib64/python3.6/urllib/request.py", line 1318, in do_open
    encode_chunked=req.has_header('Transfer-encoding'))
  File "/usr/lib64/python3.6/http/client.py", line 1254, in request
    self._send_request(method, url, body, headers, encode_chunked)
  File "/usr/lib64/python3.6/http/client.py", line 1300, in _send_request
    self.endheaders(body, encode_chunked=encode_chunked)
  File "/usr/lib64/python3.6/http/client.py", line 1249, in endheaders
    self._send_output(message_body, encode_chunked=encode_chunked)
  File "/usr/lib64/python3.6/http/client.py", line 1036, in _send_output
    self.send(msg)
  File "/usr/lib64/python3.6/http/client.py", line 974, in send
    self.connect()
  File "/usr/lib64/python3.6/http/client.py", line 946, in connect
    (self.host,self.port), self.timeout, self.source_address)
  File "/usr/lib64/python3.6/socket.py", line 724, in create_connection
    raise err
  File "/usr/lib64/python3.6/socket.py", line 713, in create_connection
    sock.connect(sa)
OSError: [Errno 113] No route to host

During handling of the above exception, another exception occurred:

Traceback (most recent call last):
  File "/root/httptracker/httptracker/ec2/ec2.py", line 30, in query
    with urllib.request.urlopen(response) as data:
  File "/usr/lib64/python3.6/urllib/request.py", line 223, in urlopen
    return opener.open(url, data, timeout)
  File "/usr/lib64/python3.6/urllib/request.py", line 526, in open
    response = self._open(req, data)
  File "/usr/lib64/python3.6/urllib/request.py", line 544, in _open
    '_open', req)
  File "/usr/lib64/python3.6/urllib/request.py", line 504, in _call_chain
    result = func(*args)
  File "/usr/lib64/python3.6/urllib/request.py", line 1346, in http_open
    return self.do_open(http.client.HTTPConnection, req)
  File "/usr/lib64/python3.6/urllib/request.py", line 1320, in do_open
    raise URLError(err)
urllib.error.URLError: <urlopen error [Errno 113] No route to host>

----------------------------------------------------------------------------------------------------
[INFO] - 2020-06-16 23:33:36,344

Source log file: /usr/local/lib64/python3.6/site-packages/django/core/servers/basehttp.py line: 157

"GET /ec2/ HTTP/1.1" 200 162
----------------------------------------------------------------------------------------------------
[INFO] - 2020-06-16 23:36:52,040

Source log file: /usr/local/lib64/python3.6/site-packages/django/utils/autoreload.py line: 222

/root/httptracker/httptracker/host/views.py changed, reloading.
----------------------------------------------------------------------------------------------------
[INFO] - 2020-06-16 23:36:52,335

Source log file: /usr/local/lib64/python3.6/site-packages/django/utils/autoreload.py line: 598

Watching for file changes with StatReloader
----------------------------------------------------------------------------------------------------
[INFO] - 2020-06-16 23:36:55,024

Source log file: /usr/local/lib64/python3.6/site-packages/django/core/servers/basehttp.py line: 157

"GET / HTTP/1.1" 200 2000
----------------------------------------------------------------------------------------------------
[INFO] - 2020-06-16 23:36:55,077

Source log file: /usr/local/lib64/python3.6/site-packages/django/core/servers/basehttp.py line: 157

"GET /static/js/jquery-3.5.1.min.js HTTP/1.1" 200 89476
----------------------------------------------------------------------------------------------------
[INFO] - 2020-06-16 23:36:56,932

Source log file: /usr/local/lib64/python3.6/site-packages/django/core/servers/basehttp.py line: 157

"GET /host HTTP/1.1" 301 0
----------------------------------------------------------------------------------------------------
[INFO] - 2020-06-16 23:36:56,936

Source log file: /usr/local/lib64/python3.6/site-packages/django/core/servers/basehttp.py line: 157

"GET /ec2 HTTP/1.1" 301 0
----------------------------------------------------------------------------------------------------
[INFO] - 2020-06-16 23:36:56,941

Source log file: /root/httptracker/httptracker/host/views.py line: 16

10.0.222.6
----------------------------------------------------------------------------------------------------
[INFO] - 2020-06-16 23:36:56,947

Source log file: /usr/local/lib64/python3.6/site-packages/django/core/servers/basehttp.py line: 157

"GET /host/ HTTP/1.1" 200 79
----------------------------------------------------------------------------------------------------
[ERROR] - 2020-06-16 23:37:00,021

Source log file: /root/httptracker/httptracker/ec2/ec2.py line: 42

Traceback (most recent call last):
  File "/usr/lib64/python3.6/urllib/request.py", line 1318, in do_open
    encode_chunked=req.has_header('Transfer-encoding'))
  File "/usr/lib64/python3.6/http/client.py", line 1254, in request
    self._send_request(method, url, body, headers, encode_chunked)
  File "/usr/lib64/python3.6/http/client.py", line 1300, in _send_request
    self.endheaders(body, encode_chunked=encode_chunked)
  File "/usr/lib64/python3.6/http/client.py", line 1249, in endheaders
    self._send_output(message_body, encode_chunked=encode_chunked)
  File "/usr/lib64/python3.6/http/client.py", line 1036, in _send_output
    self.send(msg)
  File "/usr/lib64/python3.6/http/client.py", line 974, in send
    self.connect()
  File "/usr/lib64/python3.6/http/client.py", line 946, in connect
    (self.host,self.port), self.timeout, self.source_address)
  File "/usr/lib64/python3.6/socket.py", line 724, in create_connection
    raise err
  File "/usr/lib64/python3.6/socket.py", line 713, in create_connection
    sock.connect(sa)
OSError: [Errno 113] No route to host

During handling of the above exception, another exception occurred:

Traceback (most recent call last):
  File "/root/httptracker/httptracker/ec2/ec2.py", line 30, in query
    with urllib.request.urlopen(response) as data:
  File "/usr/lib64/python3.6/urllib/request.py", line 223, in urlopen
    return opener.open(url, data, timeout)
  File "/usr/lib64/python3.6/urllib/request.py", line 526, in open
    response = self._open(req, data)
  File "/usr/lib64/python3.6/urllib/request.py", line 544, in _open
    '_open', req)
  File "/usr/lib64/python3.6/urllib/request.py", line 504, in _call_chain
    result = func(*args)
  File "/usr/lib64/python3.6/urllib/request.py", line 1346, in http_open
    return self.do_open(http.client.HTTPConnection, req)
  File "/usr/lib64/python3.6/urllib/request.py", line 1320, in do_open
    raise URLError(err)
urllib.error.URLError: <urlopen error [Errno 113] No route to host>

----------------------------------------------------------------------------------------------------
[ERROR] - 2020-06-16 23:37:03,095

Source log file: /root/httptracker/httptracker/ec2/ec2.py line: 42

Traceback (most recent call last):
  File "/usr/lib64/python3.6/urllib/request.py", line 1318, in do_open
    encode_chunked=req.has_header('Transfer-encoding'))
  File "/usr/lib64/python3.6/http/client.py", line 1254, in request
    self._send_request(method, url, body, headers, encode_chunked)
  File "/usr/lib64/python3.6/http/client.py", line 1300, in _send_request
    self.endheaders(body, encode_chunked=encode_chunked)
  File "/usr/lib64/python3.6/http/client.py", line 1249, in endheaders
    self._send_output(message_body, encode_chunked=encode_chunked)
  File "/usr/lib64/python3.6/http/client.py", line 1036, in _send_output
    self.send(msg)
  File "/usr/lib64/python3.6/http/client.py", line 974, in send
    self.connect()
  File "/usr/lib64/python3.6/http/client.py", line 946, in connect
    (self.host,self.port), self.timeout, self.source_address)
  File "/usr/lib64/python3.6/socket.py", line 724, in create_connection
    raise err
  File "/usr/lib64/python3.6/socket.py", line 713, in create_connection
    sock.connect(sa)
OSError: [Errno 113] No route to host

During handling of the above exception, another exception occurred:

Traceback (most recent call last):
  File "/root/httptracker/httptracker/ec2/ec2.py", line 30, in query
    with urllib.request.urlopen(response) as data:
  File "/usr/lib64/python3.6/urllib/request.py", line 223, in urlopen
    return opener.open(url, data, timeout)
  File "/usr/lib64/python3.6/urllib/request.py", line 526, in open
    response = self._open(req, data)
  File "/usr/lib64/python3.6/urllib/request.py", line 544, in _open
    '_open', req)
  File "/usr/lib64/python3.6/urllib/request.py", line 504, in _call_chain
    result = func(*args)
  File "/usr/lib64/python3.6/urllib/request.py", line 1346, in http_open
    return self.do_open(http.client.HTTPConnection, req)
  File "/usr/lib64/python3.6/urllib/request.py", line 1320, in do_open
    raise URLError(err)
urllib.error.URLError: <urlopen error [Errno 113] No route to host>

----------------------------------------------------------------------------------------------------
[INFO] - 2020-06-16 23:37:03,097

Source log file: /usr/local/lib64/python3.6/site-packages/django/core/servers/basehttp.py line: 157

"GET /ec2/ HTTP/1.1" 200 162
----------------------------------------------------------------------------------------------------
[INFO] - 2020-06-16 23:38:15,047

Source log file: /usr/local/lib64/python3.6/site-packages/django/utils/autoreload.py line: 222

/root/httptracker/httptracker/host/views.py changed, reloading.
----------------------------------------------------------------------------------------------------
[INFO] - 2020-06-16 23:38:15,350

Source log file: /usr/local/lib64/python3.6/site-packages/django/utils/autoreload.py line: 598

Watching for file changes with StatReloader
